Workbook

Sheet Sheet1
B3: Column Labels
B4: 2023 | J4: 2023 Total | K4: 2024 | W4: 2024 Total | X4: 2025 | AE4: 2025 Total | AF4: Grand Total
B5: May | C5: Jun | D5: Jul | E5: Aug | F5: Sep | G5: Oct | H5: Nov | I5: Dec | K5: Jan | L5: Feb | M5: Mar | N5: Apr | O5: May | P5: Jun | Q5: Jul | R5: Aug | S5: Sep | T5: Oct | U5: Nov | V5: Dec | X5: Jan | Y5: Feb | Z5: Mar | AA5: Apr | AB5: May | AC5: Jun | AD5: Jul
A6: Count of Serial Number | B6: 12 | C6: 76 | D6: 56 | E6: 86 | F6: 108 | G6: 98 | H6: 92 | I6: 160 | J6: 688 | K6: 125 | L6: 68 | M6: 103 | N6: 98 | O6: 105 | P6: 104 | Q6: 64 | R6: 80 | S6: 88 | T6: 84 | U6: 69 | V6: 115 | W6: 1103 | X6: 68 | Y6: 69 | Z6: 83 | AA6: 91 | AB6: 79 | AC6: 104 | AD6: 73 | AE6: 567 | AF6: 2358

Sheet Sheet3
A3: Row Labels | B3: Count of Dealer Name
A4: Abhishek Megamech Private Limited-C14753-BLC, FARIDABAD, HP | B4: 1
A5: Advantage Farm Equipment Ltd, Wyoming, ON-01520, Wyoming, ON | B5: 1
A6: Ag-Plus Mechanical Ltd., Medicine Hat, AB-00070, MEDICINE HAT, AB | B6: 1
A7: Agrikom, Mirabel, QC-00302, Mirabel, QC | B7: 1
A8: ASHA INFRACORE-C07923-BC, BANGALORE, KARNATAKA | B8: 2
A9: ASHA INFRACORE-C07923-BLC, Bangalore | B9: 1
A10: Atlas Bobcat, Elk Grove Village, IL-00450, ELK GROVE VILLAGE, IL | B10: 1
A11: Atlas Bobcat, Elk Grove Village., IL-00450, ELK GROVE VILLAGE, IL | B11: 16
A12: Atlas Bobcat, Mokena, IL-00275, MOKENA, IL | B12: 7
A13: Atlas Bobcat, Wauconda, IL-02198, WAUCONDA, IL | B13: 3
A14: Atlas Bobcat, West Chicago, IL-00306, WEST CHICAGO, IL | B14: 3
A15: Berchtold Equipment Co, Bakersfield, CA-00927, BAKERSFIELD, CA | B15: 18
... A512: Grand Total | B512: 2358

Sheet IRW missings
A1: IRW not added m/c no | E1: Deler side not rental
A2: B5Y211823 | E2: B5Y211049 | R2: B5Y211309
A3: B5Y212444 | E3: B5Y211066 | R3: B5Y211401
A4: B5Y213315 | E4: B5Y211086 | R4: B5Y211421
A5: B5Y213419 | E5: B5Y211114 | R5: B5Y211489
A6: B5Y213646 | E6: B5Y211123 | R6: B5Y211498
A7: B5Y213709 | E7: B5Y211228 | R7: B5Y211520
A8: B5Y213773 | E8: B5Y211251 | R8: B5Y211524
A9: B5Y213789 | E9: B5Y211348 | R9: B5Y211535
A10: B5Y213876 | E10: B5Y211452 | R10: B5Y211555
A11: B5Y213887 | E11: B5Y211474 | R11: B5Y211558
A12: B5Y213927 | E12: B5Y211629 | R12: B5Y211580
A13: B5Y213953 | E13: B5Y211658 | R13: B5Y211630
... A38: DBIB5Y2GCR0012753 | E38: B5Y212236 | R38: B5Y212004
E39: B5Y212239 | R39: B5Y212028
E40: B5Y212241 | R40: B5Y212034
E41: B5Y212261 | R41: B5Y212036
E42: B5Y212287 | R42: B5Y212039
E43: B5Y212305 | R43: B5Y212041
E44: B5Y212322 | R44: B5Y212042
E45: B5Y212347 | R45: B5Y212043
E46: B5Y212354 | R46: B5Y212044
E47: B5Y212366 | R47: B5Y212045
E48: B5Y212374 | R48: B5Y212046
E49: B5Y212377 | R49: B5Y212047
E50: B5Y212402 | R50: B5Y212048
... E144: B5Y214001 | R144: B5Y212784
E145: B5Y214003 | I145: IRW = 1335 ORACLE = 1276 DIFF=59 MATCH=1239 UNMATCH=37 | R145: B5Y212789
E146: B5Y214007 | R146: B5Y212790
E147: B5Y214008 | R147: B5Y212835
E148: B5Y214010 | R148: B5Y212842
E149: B5Y214015 | R149: B5Y212843
E150: B5Y214016 | R150: B5Y212844
E151: B5Y214017 | R151: B5Y212845
E152: B5Y214018 | R152: B5Y212857
E153: B5Y214023 | R153: B5Y212860
E154: B5Y214025 | R154: B5Y212869
E155: B5Y214028 | R155: B5Y212884
E156: B5Y214029 | R156: B5Y212886
E157: B5Y214030 | R157: B5Y212888
...

Sheet Delear Rental
A1: Serial Number | B1: Model | C1: Dealer Name | D1: Customer Name | E1: Customer Type | F1: Date of Delivery | G1: Download Date
A2: B5Y211114 | B2: S70 T4 V2 | C2: DNF, INC. BOBCAT OF SACRAMENTO-2000007774, SACRAMENTO, CA | D2: DNF, INC. BOBCAT OF SACRAMENTO-2000007774, SACRAMENTO, CA | E2: DEALERSHIP | F2: 07/07/2023
A3: B5Y211348 | B3: S70 T4 V2 | C3: BERRY COMPANIES, INC. BOBCAT OF NORTH TEXAS-LEWISVILLE-2000008213, LEWISVILLE, TX | D3: BERRY COMPANIES, INC. BOBCAT OF NORTH TEXAS-LEWISVILLE-2000008213, LEWISVILLE, TX | E3: DEALERSHIP | F3: 08/08/2023
A4: B5Y211251 | B4: S70 T4 V2 | C4: LEPPO, INC. BOBCAT OF CLEVELAND-BEDFORD HEIGHTS-4000010016, BEDFORD HEIGHTS, OH | D4: LEPPO, INC. BOBCAT OF CLEVELAND-BEDFORD HEIGHTS-4000010016, BEDFORD HEIGHTS, OH | E4: DEALERSHIP | F4: 09/21/2023
A5: B5Y211123 | B5: S70 T4 V2 | C5: LEPPO, INC. BOBCAT OF CLEVELAND-BEDFORD HEIGHTS-4000010016, BEDFORD HEIGHTS, OH | D5: LEPPO, INC. BOBCAT OF CLEVELAND-BEDFORD HEIGHTS-4000010016, BEDFORD HEIGHTS, OH | E5: DEALERSHIP | F5: 09/21/2023
A6: B5Y211049 | B6: S70 T4 V2 | C6: CARLETON EQUIPMENT COMPANY BOBCAT OF MOTOR CITY-LIVONIA-2000007759, LIVONIA, MI | D6: CARLETON EQUIPMENT COMPANY BOBCAT OF MOTOR CITY-LIVONIA-2000007759, LIVONIA, MI | E6: DEALERSHIP | F6: 11/14/2023
A7: B5Y211066 | B7: S70 T4 V2 | C7: DNF, INC. BOBCAT OF FRESNO-2000007705, FRESNO, CA | D7: DNF, INC. BOBCAT OF FRESNO-2000007705, FRESNO, CA | E7: DEALERSHIP | F7: 06/23/2023
A8: B5Y211086 | B8: S70 T4 V2 | C8: TRINITY VENTURE PARTNERS, LLC. BOBCAT OF HONOLULU-2000008048, HONOLULU, HI | D8: OLD - Service Rentals & Supplies, Hilo, HI-MATSON, HILO, HI_110000095218064_DEACTIVATED | E8: DEALERSHIP | F8: 06/14/2023
A9: B5Y212164 | B9: S70 T4 V2 | C9: BOBCAT OF CHICO INC. ICONIC MACHINERY- PITTSBURG-4000015379, PITTSBURG, CA | D9: OLD - TOTAL EQUIP & RENTAL OF THE W BOBCAT OF CONTRA COSTA-2000007772, PITTSBURG, CA | E9: DEALERSHIP | F9: 04/11/2024
A10: B5Y211658 | B10: S70 T4 V2 | C10: BINGHAM EQUIPMENT COMPANY -TUSCON-4000011938, TUCSON, AZ | D10: BINGHAM EQUIPMENT COMPANY -TUSCON-4000011938, TUCSON, AZ | E10: DEALERSHIP | F10: 06/10/2024
A11: B5Y212112 | B11: S70 T4 V2 | C11: BERRY COMPANIES, INC. BOBCAT OF NORTH TEXAS-LEWISVILLE-2000008213, LEWISVILLE, TX | D11: BERRY COMPANIES, INC. BOBCAT OF NORTH TEXAS-LEWISVILLE-2000008213, LEWISVILLE, TX | E11: DEALERSHIP | F11: 01/30/2024
A12: B5Y212121 | B12: S70 T4 V2 | C12: BOBCAT OF CHICO INC. ICONIC MACHINERY- GILROY-4000015932, GILROY, CA | D12: OLD - TOTAL EQUIP & RENTAL OF THE W BOBCAT OF GILROY-2000007824, GILROY, CA | E12: DEALERSHIP | F12: 02/08/2024
A13: B5Y212105 | B13: S70 T4 V2 | C13: BOBCAT OF CHICO INC. ICONIC MACHINERY- REDDING-2000008196, REDDING, CA | D13: BOBCAT OF CHICO INC. ICONIC MACHINERY- REDDING-2000008196, REDDING, CA | E13: DEALERSHIP | F13: 03/31/2024
... A104: B5Y212241 | B104: S70 T4 V2 | C104: BINGHAM EQUIPMENT COMPANY -CASA GRANDE-4000012072, CASA GRANDE, AZ | D104: BINGHAM EQUIPMENT COMPANY -CASA GRANDE-4000012072, CASA GRANDE, AZ | E104: DEALERSHIP | F104: 06/10/2024
A107: B5Y211305
A108: B5Y211362
A109: B5Y211411
A110: B5Y211541
A111: B5Y211579
A112: B5Y211694
A113: B5Y211721
A114: B5Y211754
A115: B5Y211768
A116: B5Y211775
A117: B5Y211782
A118: B5Y211804
... A1358: DBIB5Y2GTS0013392

Sheet S70Sheet
A1: Serial Number | B1: Model | C1: Dealer Name | D1: Customer Name | E1: Customer Type | F1: Date of Delivery | G1: Download Date | H1: Salesperson | I1: Country/region2
A2: B5Y211008 | B2: S70 T4 V2 | C2: Miramar Bobcat, San Diego, CA-06877, SAN DIEGO, CA | D2: HERNANDEZ BROTHERS LANDSCAPING | E2: CUSTOMER | F2: 45070 | G2: 45077 | H2: Matthew Jarvis
A3: B5Y211013 | B3: S70 T4 V2 | C3: SUNBELT RENTALS - PC0133-N000300, Decatur, AL | D3: SUNBELT RENTALS - PC0133-N000300, Decatur, AL | E3: NATIONALACCOUNT | F3: 45061 | G3: 45077
A4: B5Y211015 | B4: S70 T4 V2 | C4: South Coast Bobcat, Orange, CA-08461, ORANGE, CA | D4: Instant Hauling | E4: CUSTOMER | F4: 45071 | G4: 45077 | H4: Dan Arevalo
A5: B5Y211028 | B5: S70 T4 V2 | C5: Valley Bobcat, Sun Valley, CA-09467, SUN VALLEY, CA | D5: Charlie & Sons Trucking | E5: CUSTOMER | F5: 45070 | G5: 45077 | H5: Jonpierre Rejas
A6: B5Y211031 | B6: S70 T4 V2 | C6: Inland Bobcat, Riverside, CA-03080, RIVERSIDE, CA | D6: Ready Equipment Rental | E6: CUSTOMER | F6: 45063 | G6: 45077 | H6: Hector Sanchez
A7: B5Y211032 | B7: S70 T4 V2 | C7: Valley Bobcat, Sun Valley, CA-09467, SUN VALLEY, CA | D7: Server Construction, Inc. | E7: CUSTOMER | F7: 45069 | G7: 45077 | H7: Jonpierre Rejas
A8: B5Y211036 | B8: S70 T4 V2 | C8: Bobcat of the Rockies, Colorado Springs, CO-00528, COLORADO SPRINGS, CO | D8: BILLS TOOL RENTAL | E8: CUSTOMER | F8: 45071 | G8: 45077 | H8: Daniel Hankins
A9: B5Y211065 | B9: S70 T4 V2 | C9: Bobcat of the Rockies, Colorado Springs, CO-00528, COLORADO SPRINGS, CO | D9: BILLS TOOL RENTAL | E9: CUSTOMER | F9: 45071 | G9: 45077 | H9: Daniel Hankins
A10: B5Y211067 | B10: S70 T4 V2 | C10: Berchtold Equipment Co, Bakersfield, CA-00927, BAKERSFIELD, CA | D10: DO IT BEST - 6089-N106960, Rosamond, CA | E10: NATIONALACCOUNT | F10: 45064 | G10: 45077 | H10: Terry Spencer
A11: B5Y211085 | B11: S70 T4 V2 | C11: Bobcat of Ventura, Ventura, CA-08744, VENTURA, CA | D11: Antonio Benitez Landscape | E11: CUSTOMER | F11: 45071 | G11: 45077 | H11: Randy Dvorak
A12: B5Y211100 | B12: S70 T4 V2 | C12: Bobcat of Eugene, Eugene, OR-07130, EUGENE, OR | D12: Zoltan Molar | E12: CUSTOMER | F12: 45066 | G12: 45077 | H12: Brandon Weaver
A13: B5Y211104 | B13: S70 T4 V2 | C13: Bobcat of Gilroy, Gilroy, CA-02814, GILROY, CA | D13: Quynh Ngo | E13: CUSTOMER | F13: 45069 | G13: 45077 | H13: Alex Serdiuk
A14: B5Y211007 | B14: S70 T4 V2 | C14: Bobcat of Las Vegas, North Las Vegas, NV-01127, NORTH LAS VEGAS, NV | D14: Medel Repairs LLC. | E14: CUSTOMER | F14: 45091 | G14: 45104 | H14: Carlo Damelio
A15: B5Y211010 | B15: S70 T4 V2 | C15: Bobcat of Las Vegas, North Las Vegas, NV-01127, NORTH LAS VEGAS, NV | D15: GREENSCAPES OF NEVADA LLC. | E15: CUSTOMER | F15: 45093 | G15: 45104 | H15: Carlo Damelio
... A89: B5Y211369 | B89: S70 T4 V2 | C89: ASHA INFRACORE-C07923-BC, BANGALORE, KARNATAKA | D89: KIOCL LIMITED | E89: CUSTOMER | F89: 45103 | G89: 45107 | H89: Chetana Kalmane
A90: B5Y211006 | B90: S70 T4 V2 | C90: SUNSTATE EQUIPMENT - DNV-N002683, Commerce City, CO | D90: SUNSTATE EQUIPMENT - DNV-N002683, Commerce City, CO | E90: NATIONALACCOUNT | F90: 45134 | G90: 45138
A91: B5Y211039 | B91: S70 T4 V2 | C91: Bobcat of Calgary, Calgary, AB-07983, CALGARY, AB | D91: THE RENTAL GUYS.CA - CALGARY-N103500, Calgary, AB | E91: NATIONALACCOUNT | F91: 45125 | G91: 45138 | H91: Ashley Beames
A92: B5Y211042 | B92: S70 T4 V2 | C92: Sooland Bobcat, Sioux City, IA-02324, SIOUX CITY, IA | D92: Martin Diaz | E92: CUSTOMER | F92: 45113 | G92: 45138 | H92: Kevin Powell
A93: B5Y211052 | B93: S70 T4 V2 | C93: Bobcat of Toronto, Scarborough, ON-04218, SCARBOROUGH, ON | D93: Cooper Equipment Rentals Inc. | E93: CUSTOMER | F93: 45135 | G93: 45138 | H93: Kai Sorensen
A94: B5Y211059 | B94: S70 T4 V2 | C94: Bingham Equipment Co, Mesa, AZ-01056, MESA, AZ | D94: A to Z Equipment Rentals | E94: CUSTOMER | F94: 45105 | G94: 45138 | H94: Nate Stanton
A95: B5Y211071 | B95: S70 T4 V2 | C95: Bobcat of Houston/Pearland, Houston, TX-00553, HOUSTON, TX | D95: TNT TRACTOR RENTALS LLC | E95: CUSTOMER | F95: 45126 | G95: 45138 | H95: Josh Kimich
A96: B5Y211078 | B96: S70 T4 V2 | C96: Machineries Trakto, Laval, QC-00225, LAVAL, QC | D96: Delsan-Aim | E96: CUSTOMER | F96: 45111 | G96: 45138 | H96: Stevens Parker
A97: B5Y211081 | B97: S70 T4 V2 | C97: SUNSTATE EQUIPMENT - BWP-N95511, Baldwin Park, CA | D97: SUNSTATE EQUIPMENT - BWP-N95511, Baldwin Park, CA | E97: NATIONALACCOUNT | F97: 45078 | G97: 45138
A98: B5Y211090 | B98: S70 T4 V2 | C98: Bobcat of Contra Costa, Pittsburg, CA-01845, PITTSBURG, CA | D98: JAC CONSTRUCTION | E98: CUSTOMER | F98: 45121 | G98: 45138 | H98: Jay Alias
A99: B5Y211096 | B99: S70 T4 V2 | C99: Bobcat of Amarillo, Amarillo, TX-07302, AMARILLO, TX | D99: COLT MOLLOY | E99: CUSTOMER | F99: 45118 | G99: 45138 | H99: Rick Trejo
A100: B5Y211097 | B100: S70 T4 V2 | C100: SUNSTATE EQUIPMENT - BEN-N105256, Benicia, CA | D100: SUNSTATE EQUIPMENT - BEN-N105256, Benicia, CA | E100: NATIONALACCOUNT | F100: 45138 | G100: 45138 | H100: Warranty Admin
A101: B5Y211102 | B101: S70 T4 V2 | C101: SUNSTATE EQUIPMENT - BWP-N95511, Baldwin Park, CA | D101: SUNSTATE EQUIPMENT - BWP-N95511, Baldwin Park, CA | E101: NATIONALACCOUNT | F101: 45078 | G101: 45138
A102: B5Y211103 | B102: S70 T4 V2 | C102: SUNSTATE EQUIPMENT - PEO-N002423, Peoria, AZ | D102: SUNSTATE EQUIPMENT - PEO-N002423, Peoria, AZ | E102: NATIONALACCOUNT | F102: 45082 | G102: 45138
A103: B5Y211112 | B103: S70 T4 V2 | C103: Bobcat of Goleta, Goleta, CA-08743, GOLETA, CA | D103: Centerpoint | E103: CUSTOMER | F103: 45107 | G103: 45138 | H103: Jeff Wright
A104: B5Y211113 | B104: S70 T4 V2 | C104: SUNSTATE EQUIPMENT - DNV-N002683, Commerce City, CO | D104: SUNSTATE EQUIPMENT - DNV-N002683, Commerce City, CO | E104: NATIONALACCOUNT | F104: 45077 | G104: 45138
A105: B5Y211115 | B105: S70 T4 V2 | C105: Bobcat of El Paso, El Paso, TX-00573, EL PASO, TX | D105: Southwest Trucks and Equipment | E105: CUSTOMER | F105: 45086 | G105: 45138 | H105: James Napier
A106: B5Y211119 | B106: S70 T4 V2 | C106: Bobcat of Marble Falls, Marble Falls, TX-07305, Marble Falls, TX | D106: Casaperior, LLC. | E106: CUSTOMER | F106: 45120 | G106: 45138 | H106: Danny Lopez
A107: B5Y211128 | B107: S70 T4 V2 | C107: Bobcat of Salem, Salem, OR-02108, SALEM, OR | D107: Covanta-Marion County | E107: CUSTOMER | F107: 45114 | G107: 45138 | H107: Nathan Leao
A108: B5Y211131 | B108: S70 T4 V2 | C108: SUNSTATE EQUIPMENT - TUC-N002782, Tucson, AZ | D108: SUNSTATE EQUIPMENT - TUC-N002782, Tucson, AZ | E108: NATIONALACCOUNT | F108: 45082 | G108: 45138
A109: B5Y211133 | B109: S70 T4 V2 | C109: Bobcat of Sacramento, Sacramento, CA-01873, SACRAMENTO, CA | D109: MARTIN MARTINEZ PADILLA | E109: CUSTOMER | F109: 45128 | G109: 45138 | H109: Randy Erwin
A110: B5Y211135 | B110: S70 T4 V2 | C110: SUNSTATE EQUIPMENT - BWP-N95511, Baldwin Park, CA | D110: SUNSTATE EQUIPMENT - BWP-N95511, Baldwin Park, CA | E110: NATIONALACCOUNT | F110: 45078 | G110: 45138
A111: B5Y211137 | B111: S70 T4 V2 | C111: SUNSTATE EQUIPMENT - VEG-N002652, Henderson, NV | D111: SUNSTATE EQUIPMENT - VEG-N002652, Henderson, NV | E111: NATIONALACCOUNT | F111: 45083 | G111: 45138
A112: B5Y211141 | B112: S70 T4 V2 | C112: Inland Bobcat, Riverside, CA-03080, RIVERSIDE, CA | D112: JRC CONSTRUCTION | E112: CUSTOMER | F112: 45117 | G112: 45138 | H112: Art Mata
A113: B5Y211143 | B113: S70 T4 V2 | C113: Inland Bobcat, Riverside, CA-03080, RIVERSIDE, CA | D113: RUBEN FUNES | E113: CUSTOMER | F113: 45117 | G113: 45138 | H113: Art Mata
...

Sheet Sheet2
A1: Delaer Name | B1: City | C1: Countr
A2: Miramar Bobcat, San Diego, CA-06877, SAN DIEGO, CA | B2: #VALUE! | C2: #VALUE!
A3: SUNBELT RENTALS - PC0133-N000300, Decatur, AL | B3: #VALUE! | C3: #VALUE!
A4: South Coast Bobcat, Orange, CA-08461, ORANGE, CA | B4: #VALUE! | C4: #VALUE!
A5: Valley Bobcat, Sun Valley, CA-09467, SUN VALLEY, CA | B5: SUN VALLEY | C5: #VALUE!
A6: Inland Bobcat, Riverside, CA-03080, RIVERSIDE, CA | B6: #VALUE! | C6: #VALUE!
A7: Valley Bobcat, Sun Valley, CA-09467, SUN VALLEY, CA | B7: SUN VALLEY | C7: #VALUE!
A8: Bobcat of the Rockies, Colorado Springs, CO-00528, COLORADO SPRINGS, CO | B8: #VALUE! | C8: #VALUE!
A9: Bobcat of the Rockies, Colorado Springs, CO-00528, COLORADO SPRINGS, CO | B9: #VALUE! | C9: #VALUE!
A10: Berchtold Equipment Co, Bakersfield, CA-00927, BAKERSFIELD, CA | B10: #VALUE! | C10: #VALUE!
A11: Bobcat of Ventura, Ventura, CA-08744, VENTURA, CA | B11: #VALUE! | C11: #VALUE!
A12: Bobcat of Eugene, Eugene, OR-07130, EUGENE, OR | B12: #VALUE! | C12: #VALUE!
A13: Bobcat of Gilroy, Gilroy, CA-02814, GILROY, CA | B13: #VALUE! | C13: #VALUE!
A14: Bobcat of Las Vegas, North Las Vegas, NV-01127, NORTH LAS VEGAS, NV | B14: #VALUE! | C14: #VALUE!
A15: Bobcat of Las Vegas, North Las Vegas, NV-01127, NORTH LAS VEGAS, NV | B15: #VALUE! | C15: #VALUE!
A16: Bobcat of Houston, Houston, TX-00521, HOUSTON, TX | B16: #VALUE! | C16: #VALUE!
A17: South Coast Bobcat, Orange, CA-08461, ORANGE, CA | B17: #VALUE! | C17: #VALUE!
A18: Bobcat of Houston, Houston, TX-00521, HOUSTON, TX | B18: #VALUE! | C18: #VALUE!
A19: Bingham Equipment Co, Tucson, AZ-01075, TUCSON, AZ | B19: #VALUE! | C19: #VALUE!
... A29: Gage County Equipment Inc, Beatrice, NE-03536, BEATRICE, NE | B29: #VALUE! | C29: #VALUE!
A30: Bobcat of the Rockies, Parker, CO-00527, PARKER, CO | B30: PARKER | C30: #VALUE!
A31: Bingham Equipment Co, Mesa, AZ-01056, MESA, AZ | B31: #VALUE! | C31: #VALUE!
A32: Bingham Equipment Co, Tucson, AZ-01075, TUCSON, AZ | B32: #VALUE! | C32: #VALUE!
A33: Bobcat of Phoenix, Phoenix, AZ-01055, PHOENIX, AZ | B33: #VALUE! | C33: #VALUE!
A34: Bobcat of Phoenix, Phoenix, AZ-01055, PHOENIX, AZ | B34: #VALUE! | C34: #VALUE!
A35: Bobcat of Albuquerque, Albuquerque, NM-00574, ALBUQUERQUE, NM | B35: #VALUE! | C35: #VALUE!
A36: Bobcat of Albuquerque, Albuquerque, NM-00574, ALBUQUERQUE, NM | B36: #VALUE! | C36: #VALUE!
A37: Bobcat of Fresno, Fresno, CA-01119, FRESNO, CA | B37: #VALUE! | C37: #VALUE!
A38: K.C. Bobcat, Olathe, KS-05287, OLATHE, KS | B38: #VALUE! | C38: #VALUE!
A39: Bobcat of San Antonio, San Antonio, TX-07742, SAN ANTONIO, TX | B39: #VALUE! | C39: #VALUE!
A40: Bobcat of Motor City East, Chesterfield, MI-01035, CHESTERFIELD, MI | B40: CHESTERFIELD | C40: #VALUE!
A41: Bobcat of Reno, Reno, NV-01933, SPARKS, NV | B41: #VALUE! | C41: #VALUE!
A42: K.C. Bobcat, Olathe, KS-05287, OLATHE, KS | B42: #VALUE! | C42: #VALUE!
A43: Bobcat of Las Vegas, North Las Vegas, NV-01127, NORTH LAS VEGAS, NV | B43: #VALUE! | C43: #VALUE!
A44: Bobcat of Houston, Baytown, TX-09685, BAYTOWN, TX | B44: #VALUE! | C44: #VALUE!
A45: Bingham Equipment Co, Mesa, AZ-01056, MESA, AZ | B45: #VALUE! | C45: #VALUE!
A46: Bobcat of Albuquerque, Albuquerque, NM-00574, ALBUQUERQUE, NM | B46: #VALUE! | C46: #VALUE!
A47: Bobcat of Phoenix, Phoenix, AZ-01055, PHOENIX, AZ | B47: #VALUE! | C47: #VALUE!
A48: Bobcat of Las Vegas, North Las Vegas, NV-01127, NORTH LAS VEGAS, NV | B48: #VALUE! | C48: #VALUE!
A49: Bobcat of Gilroy, Gilroy, CA-02814, GILROY, CA | B49: #VALUE! | C49: #VALUE!
...

Sheet Rough
A1: Serial Number | B1: Model | C1: Dealer Name | D1: City | E1: Country/region | F1: Customer Name | G1: Customer Type | H1: Reported Stolen | I1: Reported Stolen Date | J1: Date of Delivery | K1: Download Date | L1: Salesperson
A2: B5Y211008 | B2: S70 T4 V2 | C2: Miramar Bobcat, San Diego, CA-06877, SAN DIEGO, CA | D2: #VALUE! | E2: #VALUE! | F2: HERNANDEZ BROTHERS LANDSCAPING | G2: CUSTOMER | J2: 45070 | K2: 45077 | L2: Matthew Jarvis
A3: B5Y211013 | B3: S70 T4 V2 | C3: SUNBELT RENTALS - PC0133-N000300, Decatur, AL | D3: #VALUE! | E3: #VALUE! | F3: SUNBELT RENTALS - PC0133-N000300, Decatur, AL | G3: NATIONALACCOUNT | J3: 45061 | K3: 45077
A4: B5Y211015 | B4: S70 T4 V2 | C4: South Coast Bobcat, Orange, CA-08461, ORANGE, CA | D4: #VALUE! | E4: #VALUE! | F4: Instant Hauling | G4: CUSTOMER | J4: 45071 | K4: 45077 | L4: Dan Arevalo
A5: B5Y211028 | B5: S70 T4 V2 | C5: Valley Bobcat, Sun Valley, CA-09467, SUN VALLEY, CA | D5: SUN VALLEY | E5: #VALUE! | F5: Charlie & Sons Trucking | G5: CUSTOMER | J5: 45070 | K5: 45077 | L5: Jonpierre Rejas
A6: B5Y211031 | B6: S70 T4 V2 | C6: Inland Bobcat, Riverside, CA-03080, RIVERSIDE, CA | D6: #VALUE! | E6: #VALUE! | F6: Ready Equipment Rental | G6: CUSTOMER | J6: 45063 | K6: 45077 | L6: Hector Sanchez
A7: B5Y211032 | B7: S70 T4 V2 | C7: Valley Bobcat, Sun Valley, CA-09467, SUN VALLEY, CA | D7: SUN VALLEY | E7: #VALUE! | F7: Server Construction, Inc. | G7: CUSTOMER | J7: 45069 | K7: 45077 | L7: Jonpierre Rejas
A8: B5Y211036 | B8: S70 T4 V2 | C8: Bobcat of the Rockies, Colorado Springs, CO-00528, COLORADO SPRINGS, CO | D8: #VALUE! | E8: #VALUE! | F8: BILLS TOOL RENTAL | G8: CUSTOMER | J8: 45071 | K8: 45077 | L8: Daniel Hankins
A9: B5Y211065 | B9: S70 T4 V2 | C9: Bobcat of the Rockies, Colorado Springs, CO-00528, COLORADO SPRINGS, CO | D9: #VALUE! | E9: #VALUE! | F9: BILLS TOOL RENTAL | G9: CUSTOMER | J9: 45071 | K9: 45077 | L9: Daniel Hankins
A10: B5Y211067 | B10: S70 T4 V2 | C10: Berchtold Equipment Co, Bakersfield, CA-00927, BAKERSFIELD, CA | D10: #VALUE! | E10: #VALUE! | F10: DO IT BEST - 6089-N106960, Rosamond, CA | G10: NATIONALACCOUNT | J10: 45064 | K10: 45077 | L10: Terry Spencer
A11: B5Y211085 | B11: S70 T4 V2 | C11: Bobcat of Ventura, Ventura, CA-08744, VENTURA, CA | D11: #VALUE! | E11: #VALUE! | F11: Antonio Benitez Landscape | G11: CUSTOMER | J11: 45071 | K11: 45077 | L11: Randy Dvorak
A12: B5Y211100 | B12: S70 T4 V2 | C12: Bobcat of Eugene, Eugene, OR-07130, EUGENE, OR | D12: #VALUE! | E12: #VALUE! | F12: Zoltan Molar | G12: CUSTOMER | J12: 45066 | K12: 45077 | L12: Brandon Weaver
A13: B5Y211104 | B13: S70 T4 V2 | C13: Bobcat of Gilroy, Gilroy, CA-02814, GILROY, CA | D13: #VALUE! | E13: #VALUE! | F13: Quynh Ngo | G13: CUSTOMER | J13: 45069 | K13: 45077 | L13: Alex Serdiuk
A14: B5Y211007 | B14: S70 T4 V2 | C14: Bobcat of Las Vegas, North Las Vegas, NV-01127, NORTH LAS VEGAS, NV | D14: #VALUE! | E14: #VALUE! | F14: Medel Repairs LLC. | G14: CUSTOMER | J14: 45091 | K14: 45104 | L14: Carlo Damelio
A15: B5Y211010 | B15: S70 T4 V2 | C15: Bobcat of Las Vegas, North Las Vegas, NV-01127, NORTH LAS VEGAS, NV | D15: #VALUE! | E15: #VALUE! | F15: GREENSCAPES OF NEVADA LLC. | G15: CUSTOMER | J15: 45093 | K15: 45104 | L15: Carlo Damelio
A16: B5Y211011 | B16: S70 T4 V2 | C16: Bobcat of Houston, Houston, TX-00521, HOUSTON, TX | D16: #VALUE! | E16: #VALUE! | F16: INDUSTRIAL TX CORP | G16: CUSTOMER | J16: 45076 | K16: 45104 | L16: Daniel von Gontard
A17: B5Y211012 | B17: S70 T4 V2 | C17: South Coast Bobcat, Orange, CA-08461, ORANGE, CA | D17: #VALUE! | E17: #VALUE! | F17: Munoz Hauling Inc. | G17: CUSTOMER | J17: 45092 | K17: 45104 | L17: Dan Arevalo
A18: B5Y211014 | B18: S70 T4 V2 | C18: Bobcat of Houston, Houston, TX-00521, HOUSTON, TX | D18: #VALUE! | E18: #VALUE! | F18: G.C. HOMES AND INVESTMENTS LLC | G18: CUSTOMER | J18: 45077 | K18: 45104 | L18: Josh Kimich
A19: B5Y211017 | B19: S70 T4 V2 | C19: Bingham Equipment Co, Tucson, AZ-01075, TUCSON, AZ | D19: #VALUE! | E19: #VALUE! | F19: Southwest Equipment LLC | G19: CUSTOMER | J19: 45073 | K19: 45104 | L19: Victor Lopez
... A29: B5Y211041 | B29: S70 T4 V2 | C29: Gage County Equipment Inc, Beatrice, NE-03536, BEATRICE, NE | D29: #VALUE! | E29: #VALUE! | F29: Eric Engelman | G29: CUSTOMER | J29: 45093 | K29: 45104 | L29: Dale Zimmerman
A30: B5Y211053 | B30: S70 T4 V2 | C30: Bobcat of the Rockies, Parker, CO-00527, PARKER, CO | D30: PARKER | E30: #VALUE! | F30: KELLEY SPRINKLER AND LANDSCAPE | G30: CUSTOMER | J30: 45092 | K30: 45104 | L30: Rollie McDaniel
A31: B5Y211060 | B31: S70 T4 V2 | C31: Bingham Equipment Co, Mesa, AZ-01056, MESA, AZ | D31: #VALUE! | E31: #VALUE! | F31: Teresa Bautista | G31: CUSTOMER | J31: 45076 | K31: 45104 | L31: Brandon Townsend
A32: B5Y211062 | B32: S70 T4 V2 | C32: Bingham Equipment Co, Tucson, AZ-01075, TUCSON, AZ | D32: #VALUE! | E32: #VALUE! | F32: LANDSCAPE SOLUTIONS | G32: CUSTOMER | J32: 45079 | K32: 45104 | L32: Victor Lopez
A33: B5Y211064 | B33: S70 T4 V2 | C33: Bobcat of Phoenix, Phoenix, AZ-01055, PHOENIX, AZ | D33: #VALUE! | E33: #VALUE! | F33: MasterAZscapes LLC | G33: CUSTOMER | J33: 45089 | K33: 45104 | L33: Gary Walker
A34: B5Y211068 | B34: S70 T4 V2 | C34: Bobcat of Phoenix, Phoenix, AZ-01055, PHOENIX, AZ | D34: #VALUE! | E34: #VALUE! | F34: MasterAZscapes LLC | G34: CUSTOMER | J34: 45089 | K34: 45104 | L34: Gary Walker
A35: B5Y211069 | B35: S70 T4 V2 | C35: Bobcat of Albuquerque, Albuquerque, NM-00574, ALBUQUERQUE, NM | D35: #VALUE! | E35: #VALUE! | F35: RAC Construction, INC. | G35: CUSTOMER | J35: 45086 | K35: 45104 | L35: Miguel Merino
A36: B5Y211070 | B36: S70 T4 V2 | C36: Bobcat of Albuquerque, Albuquerque, NM-00574, ALBUQUERQUE, NM | D36: #VALUE! | E36: #VALUE! | F36: FRANKS SUPPLY CO | G36: CUSTOMER | J36: 45071 | K36: 45104 | L36: Miguel Merino
A37: B5Y211074 | B37: S70 T4 V2 | C37: Bobcat of Fresno, Fresno, CA-01119, FRESNO, CA | D37: #VALUE! | E37: #VALUE! | F37: SALAS CONCRETE | G37: CUSTOMER | J37: 45072 | K37: 45104 | L37: Ryan Wilson
A38: B5Y211077 | B38: S70 T4 V2 | C38: K.C. Bobcat, Olathe, KS-05287, OLATHE, KS | D38: #VALUE! | E38: #VALUE! | F38: The Monarch Cement Company | G38: CUSTOMER | J38: 45076 | K38: 45104 | L38: Derek Diederich
A39: B5Y211080 | B39: S70 T4 V2 | C39: Bobcat of San Antonio, San Antonio, TX-07742, SAN ANTONIO, TX | D39: #VALUE! | E39: #VALUE! | F39: WATSONSUPERSTORE OF SAN ANTONIO INC. | G39: CUSTOMER | J39: 45089 | K39: 45104 | L39: Eli Esquivel
A40: B5Y211083 | B40: S70 T4 V2 | C40: Bobcat of Motor City East, Chesterfield, MI-01035, CHESTERFIELD, MI | D40: CHESTERFIELD | E40: #VALUE! | F40: Max Demolition | G40: CUSTOMER | J40: 45079 | K40: 45104 | L40: Ray Henwood
A41: B5Y211084 | B41: S70 T4 V2 | C41: Bobcat of Reno, Reno, NV-01933, SPARKS, NV | D41: #VALUE! | E41: #VALUE! | F41: QUALITY INYO CONCRETE | G41: CUSTOMER | J41: 45097 | K41: 45104 | L41: Karl Tremblay
A42: B5Y211087 | B42: S70 T4 V2 | C42: K.C. Bobcat, Olathe, KS-05287, OLATHE, KS | D42: #VALUE! | E42: #VALUE! | F42: The Monarch Cement Company | G42: CUSTOMER | J42: 45076 | K42: 45104 | L42: Derek Diederich
A43: B5Y211092 | B43: S70 T4 V2 | C43: Bobcat of Las Vegas, North Las Vegas, NV-01127, NORTH LAS VEGAS, NV | D43: #VALUE! | E43: #VALUE! | F43: ALPHA LANDSCAPES | G43: CUSTOMER | J43: 45096 | K43: 45104 | L43: Carlo Damelio
A44: B5Y211093 | B44: S70 T4 V2 | C44: Bobcat of Houston, Baytown, TX-09685, BAYTOWN, TX | D44: #VALUE! | E44: #VALUE! | F44: G.C. HOMES AND INVESTMENTS LLC | G44: CUSTOMER | J44: 45072 | K44: 45104 | L44: Josh Kimich
A45: B5Y211094 | B45: S70 T4 V2 | C45: Bingham Equipment Co, Mesa, AZ-01056, MESA, AZ | D45: #VALUE! | E45: #VALUE! | F45: GDL CONSTRUCTION PRO LLC | G45: CUSTOMER | J45: 45097 | K45: 45104 | L45: Ashley Ghose
A46: B5Y211095 | B46: S70 T4 V2 | C46: Bobcat of Albuquerque, Albuquerque, NM-00574, ALBUQUERQUE, NM | D46: #VALUE! | E46: #VALUE! | F46: RAC Construction, INC. | G46: CUSTOMER | J46: 45086 | K46: 45104 | L46: Miguel Merino
A47: B5Y211098 | B47: S70 T4 V2 | C47: Bobcat of Phoenix, Phoenix, AZ-01055, PHOENIX, AZ | D47: #VALUE! | E47: #VALUE! | F47: Home Builders Site Service AZ | G47: CUSTOMER | J47: 45090 | K47: 45104 | L47: Gary Walker
A48: B5Y211106 | B48: S70 T4 V2 | C48: Bobcat of Las Vegas, North Las Vegas, NV-01127, NORTH LAS VEGAS, NV | D48: #VALUE! | E48: #VALUE! | F48: ALPHA LANDSCAPES | G48: CUSTOMER | J48: 45096 | K48: 45104 | L48: Carlo Damelio
A49: B5Y211107 | B49: S70 T4 V2 | C49: Bobcat of Gilroy, Gilroy, CA-02814, GILROY, CA | D49: #VALUE! | E49: #VALUE! | F49: Quynh Ngo | G49: CUSTOMER | J49: 45097 | K49: 45104 | L49: Alex Serdiuk
...

Sheet Delaer Name_City
A1: Dealer Name | B1: City
A2: Miramar Bobcat, San Diego, CA-06877, SAN DIEGO, CA | B2: #VALUE!
A3: SUNBELT RENTALS - PC0133-N000300, Decatur, AL | B3: #VALUE!
A4: South Coast Bobcat, Orange, CA-08461, ORANGE, CA | B4: #VALUE!
A5: Valley Bobcat, Sun Valley, CA-09467, SUN VALLEY, CA | B5: SUN VALLEY
A6: Inland Bobcat, Riverside, CA-03080, RIVERSIDE, CA | B6: #VALUE!
A7: Valley Bobcat, Sun Valley, CA-09467, SUN VALLEY, CA | B7: SUN VALLEY
A8: Bobcat of the Rockies, Colorado Springs, CO-00528, COLORADO SPRINGS, CO | B8: #VALUE!
A9: Bobcat of the Rockies, Colorado Springs, CO-00528, COLORADO SPRINGS, CO | B9: #VALUE!
A10: Berchtold Equipment Co, Bakersfield, CA-00927, BAKERSFIELD, CA | B10: #VALUE!
A11: Bobcat of Ventura, Ventura, CA-08744, VENTURA, CA | B11: #VALUE!
A12: Bobcat of Eugene, Eugene, OR-07130, EUGENE, OR | B12: #VALUE!
A13: Bobcat of Gilroy, Gilroy, CA-02814, GILROY, CA | B13: #VALUE!
A14: Bobcat of Las Vegas, North Las Vegas, NV-01127, NORTH LAS VEGAS, NV | B14: #VALUE!
A15: Bobcat of Las Vegas, North Las Vegas, NV-01127, NORTH LAS VEGAS, NV | B15: #VALUE!
A16: Bobcat of Houston, Houston, TX-00521, HOUSTON, TX | B16: #VALUE!
A17: South Coast Bobcat, Orange, CA-08461, ORANGE, CA | B17: #VALUE!
A18: Bobcat of Houston, Houston, TX-00521, HOUSTON, TX | B18: #VALUE!
A19: Bingham Equipment Co, Tucson, AZ-01075, TUCSON, AZ | B19: #VALUE!
... A29: Gage County Equipment Inc, Beatrice, NE-03536, BEATRICE, NE | B29: #VALUE!
A30: Bobcat of the Rockies, Parker, CO-00527, PARKER, CO | B30: PARKER
A31: Bingham Equipment Co, Mesa, AZ-01056, MESA, AZ | B31: #VALUE!
A32: Bingham Equipment Co, Tucson, AZ-01075, TUCSON, AZ | B32: #VALUE!
A33: Bobcat of Phoenix, Phoenix, AZ-01055, PHOENIX, AZ | B33: #VALUE!
A34: Bobcat of Phoenix, Phoenix, AZ-01055, PHOENIX, AZ | B34: #VALUE!
A35: Bobcat of Albuquerque, Albuquerque, NM-00574, ALBUQUERQUE, NM | B35: #VALUE!
A36: Bobcat of Albuquerque, Albuquerque, NM-00574, ALBUQUERQUE, NM | B36: #VALUE!
A37: Bobcat of Fresno, Fresno, CA-01119, FRESNO, CA | B37: #VALUE!
A38: K.C. Bobcat, Olathe, KS-05287, OLATHE, KS | B38: #VALUE!
A39: Bobcat of San Antonio, San Antonio, TX-07742, SAN ANTONIO, TX | B39: #VALUE!
A40: Bobcat of Motor City East, Chesterfield, MI-01035, CHESTERFIELD, MI | B40: CHESTERFIELD
A41: Bobcat of Reno, Reno, NV-01933, SPARKS, NV | B41: #VALUE!
A42: K.C. Bobcat, Olathe, KS-05287, OLATHE, KS | B42: #VALUE!
A43: Bobcat of Las Vegas, North Las Vegas, NV-01127, NORTH LAS VEGAS, NV | B43: #VALUE!
A44: Bobcat of Houston, Baytown, TX-09685, BAYTOWN, TX | B44: #VALUE!
A45: Bingham Equipment Co, Mesa, AZ-01056, MESA, AZ | B45: #VALUE!
A46: Bobcat of Albuquerque, Albuquerque, NM-00574, ALBUQUERQUE, NM | B46: #VALUE!
A47: Bobcat of Phoenix, Phoenix, AZ-01055, PHOENIX, AZ | B47: #VALUE!
A48: Bobcat of Las Vegas, North Las Vegas, NV-01127, NORTH LAS VEGAS, NV | B48: #VALUE!
A49: Bobcat of Gilroy, Gilroy, CA-02814, GILROY, CA | B49: #VALUE!
...

Sheet Sheet0 (2)
A1: Serial Number | B1: Model | C1: Dealer Name | D1: Customer Name | E1: Customer Type | F1: Reported Stolen | G1: Reported Stolen Date | H1: Date of Delivery | I1: Machine Age | J1: Salesperson | L1: Machine Number
A2: B5Y211004 | B2: S70 T4 V2 | C2: Bingham Equipment Co, Mesa, AZ-01056, MESA, AZ | D2: A to Z Equipment Rentals | E2: CUSTOMER | H2: 06/20/2023 | I2: 24 | J2: Brandon Townsend | L2: =_xlfn.XLOOKUP(A2,S70Sheet!A:A,S70Sheet!A:A)
A3: B5Y211005 | B3: S70 T4 V2 | C3: Bingham Equipment Co, Mesa, AZ-01056, MESA, AZ | D3: A to Z Equipment Rentals | E3: CUSTOMER | H3: 06/20/2023 | I3: 24 | J3: Nate Stanton | L3: =_xlfn.XLOOKUP(A3,S70Sheet!A:A,S70Sheet!A:A)
A4: B5Y211006 | B4: S70 T4 V2 | C4: SUNSTATE EQUIPMENT - DNV-N002683, Commerce City, CO | D4: SUNSTATE EQUIPMENT - DNV-N002683, Commerce City, CO | E4: NATIONALACCOUNT | H4: 07/27/2023 | I4: 22 | L4: =_xlfn.XLOOKUP(A4,S70Sheet!A:A,S70Sheet!A:A)
A5: B5Y211007 | B5: S70 T4 V2 | C5: Bobcat of Las Vegas, North Las Vegas, NV-01127, NORTH LAS VEGAS, NV | D5: Medel Repairs LLC. | E5: CUSTOMER | H5: 06/14/2023 | I5: 24 | J5: Carlo Damelio | L5: =_xlfn.XLOOKUP(A5,S70Sheet!A:A,S70Sheet!A:A)
A6: B5Y211008 | B6: S70 T4 V2 | C6: Miramar Bobcat, San Diego, CA-06877, SAN DIEGO, CA | D6: HERNANDEZ BROTHERS LANDSCAPING | E6: CUSTOMER | H6: 05/24/2023 | I6: 24 | J6: Matthew Jarvis | L6: =_xlfn.XLOOKUP(A6,S70Sheet!A:A,S70Sheet!A:A)
A7: B5Y211009 | B7: S70 T4 V2 | C7: Bobcat of Las Vegas, North Las Vegas, NV-01127, NORTH LAS VEGAS, NV | D7: TORO CONSULTING | E7: CUSTOMER | H7: 06/28/2023 | I7: 24 | J7: Carlo Damelio | L7: =_xlfn.XLOOKUP(A7,S70Sheet!A:A,S70Sheet!A:A)
A8: B5Y211010 | B8: S70 T4 V2 | C8: Bobcat of Las Vegas, North Las Vegas, NV-01127, NORTH LAS VEGAS, NV | D8: GREENSCAPES OF NEVADA LLC. | E8: CUSTOMER | H8: 06/16/2023 | I8: 24 | J8: Carlo Damelio | L8: =_xlfn.XLOOKUP(A8,S70Sheet!A:A,S70Sheet!A:A)
A9: B5Y211011 | B9: S70 T4 V2 | C9: Bobcat of Houston, Houston, TX-00521, HOUSTON, TX | D9: INDUSTRIAL TX CORP | E9: CUSTOMER | H9: 05/30/2023 | I9: 24 | J9: Daniel von Gontard | L9: =_xlfn.XLOOKUP(A9,S70Sheet!A:A,S70Sheet!A:A)
A10: B5Y211012 | B10: S70 T4 V2 | C10: South Coast Bobcat, Orange, CA-08461, ORANGE, CA | D10: Munoz Hauling Inc. | E10: CUSTOMER | H10: 06/15/2023 | I10: 24 | J10: Dan Arevalo | L10: =_xlfn.XLOOKUP(A10,S70Sheet!A:A,S70Sheet!A:A)
A11: B5Y211013 | B11: S70 T4 V2 | C11: SUNBELT RENTALS - PC0133-N000300, Decatur, AL | D11: SUNBELT RENTALS - PC0133-N000300, Decatur, AL | E11: NATIONALACCOUNT | H11: 05/15/2023 | I11: 24 | L11: =_xlfn.XLOOKUP(A11,S70Sheet!A:A,S70Sheet!A:A)
A12: B5Y211014 | B12: S70 T4 V2 | C12: Bobcat of Houston, Houston, TX-00521, HOUSTON, TX | D12: G.C. HOMES AND INVESTMENTS LLC | E12: CUSTOMER | H12: 05/31/2023 | I12: 24 | J12: Josh Kimich | L12: =_xlfn.XLOOKUP(A12,S70Sheet!A:A,S70Sheet!A:A)
A13: B5Y211015 | B13: S70 T4 V2 | C13: South Coast Bobcat, Orange, CA-08461, ORANGE, CA | D13: Instant Hauling | E13: CUSTOMER | H13: 05/25/2023 | I13: 24 | J13: Dan Arevalo | L13: =_xlfn.XLOOKUP(A13,S70Sheet!A:A,S70Sheet!A:A)
A14: B5Y211016 | B14: S70 T4 V2 | C14: Bobcat of Las Vegas, North Las Vegas, NV-01127, NORTH LAS VEGAS, NV | D14: AZ LANDSCAPE & HAULING | E14: CUSTOMER | H14: 06/26/2023 | I14: 24 | J14: Carlo Damelio | L14: =_xlfn.XLOOKUP(A14,S70Sheet!A:A,S70Sheet!A:A)
A15: B5Y211017 | B15: S70 T4 V2 | C15: Bingham Equipment Co, Tucson, AZ-01075, TUCSON, AZ | D15: Southwest Equipment LLC | E15: CUSTOMER | H15: 05/27/2023 | I15: 24 | J15: Victor Lopez | L15: =_xlfn.XLOOKUP(A15,S70Sheet!A:A,S70Sheet!A:A)
A16: B5Y211018 | B16: S70 T4 V2 | C16: Bingham Equipment Co, Tucson, AZ-01075, TUCSON, AZ | D16: Desert Valley Landscaping | E16: CUSTOMER | H16: 06/09/2023 | I16: 24 | J16: Victor Lopez | L16: =_xlfn.XLOOKUP(A16,S70Sheet!A:A,S70Sheet!A:A)
A17: B5Y211019 | B17: S70 T4 V2 | C17: HERC RENTALS - 09722-N000298, Fife, WA | D17: HERC RENTALS - 09722-N000298, Fife, WA | E17: NATIONALACCOUNT | H17: 11/17/2023 | I17: 18 | L17: =_xlfn.XLOOKUP(A17,S70Sheet!A:A,S70Sheet!A:A)
A18: B5Y211020 | B18: S70 T4 V2 | C18: Bobcat of Miami, Hialeah Gardens, FL-03010, DORAL, FL | D18: equipment and tools solution | E18: CUSTOMER | H18: 06/19/2023 | I18: 24 | J18: Lucas DeSouza | L18: =_xlfn.XLOOKUP(A18,S70Sheet!A:A,S70Sheet!A:A)
A19: B5Y211021 | B19: S70 T4 V2 | C19: HERC RENTALS - 09633-N000335, N Hollywood, CA | D19: HERC RENTALS - 09633-N000335, N Hollywood, CA | E19: NATIONALACCOUNT | H19: 11/21/2023 | I19: 18 | L19: =_xlfn.XLOOKUP(A19,S70Sheet!A:A,S70Sheet!A:A)
A20: B5Y211022 | B20: S70 T4 V2 | C20: HERC RENTALS - 09644-N000644, Fresno, CA | D20: HERC RENTALS - 09644-N000644, Fresno, CA | E20: NATIONALACCOUNT | H20: 11/20/2023 | I20: 18 | L20: =_xlfn.XLOOKUP(A20,S70Sheet!A:A,S70Sheet!A:A)
A21: B5Y211023 | B21: S70 T4 V2 | C21: Bobcat of Los Angeles., Cerritos, CA-06879, CERRITOS, CA | D21: ZR Equipment Rentals, LLC | E21: CUSTOMER | H21: 10/27/2023 | I21: 19 | J21: Benjamin Nunez | L21: =_xlfn.XLOOKUP(A21,S70Sheet!A:A,S70Sheet!A:A)
A22: B5Y211024 | B22: S70 T4 V2 | C22: Bobcat of New York City, Maspeth, NY-08828, MASPETH, NY | D22: paul johnson custom bldg | E22: CUSTOMER | H22: 06/21/2023 | I22: 24 | J22: Jim Badaracco | L22: =_xlfn.XLOOKUP(A22,S70Sheet!A:A,S70Sheet!A:A)
A23: B5Y211025 | B23: S70 T4 V2 | C23: HERC RENTALS - 09661-N001678, Las Vegas, NV | D23: HERC RENTALS - 09661-N001678, Las Vegas, NV | E23: NATIONALACCOUNT | H23: 11/21/2023 | I23: 18 | L23: =_xlfn.XLOOKUP(A23,S70Sheet!A:A,S70Sheet!A:A)
A24: B5Y211026 | B24: S70 T4 V2 | C24: Bingham Equipment Co, Mesa, AZ-01056, MESA, AZ | D24: Victor Alvarez | E24: CUSTOMER | H24: 06/07/2023 | I24: 24 | J24: Brandon Townsend | L24: =_xlfn.XLOOKUP(A24,S70Sheet!A:A,S70Sheet!A:A)
A25: B5Y211027 | B25: S70 T4 V2 | C25: Bobcat of Los Angeles., Cerritos, CA-06879, CERRITOS, CA | D25: FP CONCRETE | E25: CUSTOMER | H25: 06/09/2023 | I25: 24 | J25: Benjamin Nunez | L25: =_xlfn.XLOOKUP(A25,S70Sheet!A:A,S70Sheet!A:A)
A26: B5Y211028 | B26: S70 T4 V2 | C26: Valley Bobcat, Sun Valley, CA-09467, SUN VALLEY, CA | D26: Charlie & Sons Trucking | E26: CUSTOMER | H26: 05/24/2023 | I26: 24 | J26: Jonpierre Rejas | L26: =_xlfn.XLOOKUP(A26,S70Sheet!A:A,S70Sheet!A:A)
A27: B5Y211029 | B27: S70 T4 V2 | C27: Bobcat of Las Vegas, North Las Vegas, NV-01127, NORTH LAS VEGAS, NV | D27: ALPHA LANDSCAPES | E27: CUSTOMER | H27: 06/19/2023 | I27: 24 | J27: Carlo Damelio | L27: =_xlfn.XLOOKUP(A27,S70Sheet!A:A,S70Sheet!A:A)
A28: B5Y211030 | B28: S70 T4 V2 | C28: Bobcat of Fremont, Fremont, CA-05319, FREMONT, CA | D28: ARTLAND | E28: CUSTOMER | H28: 06/05/2023 | I28: 24 | J28: Luis Martinez | L28: =_xlfn.XLOOKUP(A28,S70Sheet!A:A,S70Sheet!A:A)
A29: B5Y211031 | B29: S70 T4 V2 | C29: Inland Bobcat, Riverside, CA-03080, RIVERSIDE, CA | D29: Paul Cantor | E29: CUSTOMER | H29: 05/17/2023 | I29: 24 | J29: Hector Sanchez | L29: =_xlfn.XLOOKUP(A29,S70Sheet!A:A,S70Sheet!A:A)
A30: B5Y211032 | B30: S70 T4 V2 | C30: Valley Bobcat, Sun Valley, CA-09467, SUN VALLEY, CA | D30: Server Construction, Inc. | E30: CUSTOMER | H30: 05/23/2023 | I30: 24 | J30: Jonpierre Rejas | L30: =_xlfn.XLOOKUP(A30,S70Sheet!A:A,S70Sheet!A:A)
A31: B5Y211033 | B31: S70 T4 V2 | C31: Bobcat of Albuquerque, Albuquerque, NM-00574, ALBUQUERQUE, NM | D31: FRANKS SUPPLY CO INC | E31: CUSTOMER | H31: 06/27/2023 | I31: 23 | J31: Miguel Merino | L31: =_xlfn.XLOOKUP(A31,S70Sheet!A:A,S70Sheet!A:A)
A32: B5Y211034 | B32: S70 T4 V2 | C32: Bobcat of Lakeland, Lakeland, FL-08946, LAKELAND, FL | D32: RINKER MATERIALS | E32: CUSTOMER | H32: 08/21/2023 | I32: 24 | J32: Tim Wellman | L32: =_xlfn.XLOOKUP(A32,S70Sheet!A:A,S70Sheet!A:A)
A33: B5Y211035 | B33: S70 T4 V2 | C33: Inland Bobcat, Riverside, CA-03080, RIVERSIDE, CA | D33: ROSOCA CONSTRUCTION CO | E33: CUSTOMER | H33: 05/30/2023 | I33: 24 | J33: Art Mata | L33: =_xlfn.XLOOKUP(A33,S70Sheet!A:A,S70Sheet!A:A)
A34: B5Y211036 | B34: S70 T4 V2 | C34: Bobcat of the Rockies, Colorado Springs, CO-00528, COLORADO SPRINGS, CO | D34: BILLS TOOL RENTAL | E34: CUSTOMER | H34: 05/25/2023 | I34: 24 | J34: Daniel Hankins | L34: =_xlfn.XLOOKUP(A34,S70Sheet!A:A,S70Sheet!A:A)
A35: B5Y211037 | B35: S70 T4 V2 | C35: Bingham Equipment Co, Buckeye, AZ-01068, BUCKEYE, AZ | D35: GC 360 LLC | E35: CUSTOMER | H35: 06/27/2023 | I35: 24 | J35: Josh Rodriguez | L35: =_xlfn.XLOOKUP(A35,S70Sheet!A:A,S70Sheet!A:A)
... A48: B5Y211051 | B48: S70 T4 V2 | C48: Bobcat of Anderson, Anderson, IN-00513, ANDERSON, IN | D48: BECK'S - TOM HOOPER-N107059, Atlanta, IN | E48: NATIONALACCOUNT | H48: 06/23/2023 | I48: 23 | J48: Chris Wooldridge | L48: =_xlfn.XLOOKUP(A48,S70Sheet!A:A,S70Sheet!A:A)
A49: B5Y211052 | B49: S70 T4 V2 | C49: COOPER EQUIPMENT RENTALS LTD-2793331, MISSISSAUGA, ON | D49: COOPER EQUIPMENT RENTALS LTD-2793331, MISSISSAUGA, ON | E49: NATIONALACCOUNT | H49: 07/28/2023 | I49: 22 | L49: =_xlfn.XLOOKUP(A49,S70Sheet!A:A,S70Sheet!A:A)
A50: B5Y211053 | B50: S70 T4 V2 | C50: Bobcat of the Rockies, Parker, CO-00527, PARKER, CO | D50: KELLEY SPRINKLER AND LANDSCAPE | E50: CUSTOMER | H50: 06/15/2023 | I50: 24 | J50: Rollie McDaniel | L50: =_xlfn.XLOOKUP(A50,S70Sheet!A:A,S70Sheet!A:A)
A51: B5Y211054 | B51: S70 T4 V2 | C51: UNITED RENTALS 801-N96333, Everett, MA | D51: UNITED RENTALS 801-N96333, Everett, MA | E51: NATIONALACCOUNT | H51: 08/08/2023 | I51: 21 | L51: =_xlfn.XLOOKUP(A51,S70Sheet!A:A,S70Sheet!A:A)
A52: B5Y211055 | B52: S70 T4 V2 | C52: Bobcat of West Chester, West Chester, PA-00280, WEST CHESTER, PA | D52: Guizzetti & SOns | E52: CUSTOMER | H52: 12/06/2023 | I52: 20 | J52: Fred Ferrentino | L52: =_xlfn.XLOOKUP(A52,S70Sheet!A:A,S70Sheet!A:A)
...

Sheet Sheet4
B2: Dealer Name
B3: Abhishek Megamech Private Limited-C14753-BLC, FARIDABAD, HP
B4: Advantage Farm Equipment Ltd, Wyoming, ON-01520, Wyoming, ON
B5: Ag-Plus Mechanical Ltd., Medicine Hat, AB-00070, MEDICINE HAT, AB
B6: Agrikom, Mirabel, QC-00302, Mirabel, QC
B7: ASHA INFRACORE-C07923-BC, BANGALORE, KARNATAKA
B8: ASHA INFRACORE-C07923-BLC, Bangalore
B9: Atlas Bobcat, Elk Grove Village, IL-00450, ELK GROVE VILLAGE, IL
B10: Atlas Bobcat, Elk Grove Village., IL-00450, ELK GROVE VILLAGE, IL
B11: Atlas Bobcat, Mokena, IL-00275, MOKENA, IL
B12: Atlas Bobcat, Wauconda, IL-02198, WAUCONDA, IL
B13: Atlas Bobcat, West Chicago, IL-00306, WEST CHICAGO, IL
... B510: YOLO EXIMCARE PRIVATE LIMITED-C14775-BLC, Ranchi, JK
